Workbook

Sheet budget
A1: Category | B1: Line Item | C1: Timing (Pre/During/Post) | D1: Qty | E1: Unit Cost | F1: Fixed/Variable | G1: Low | H1: Mid | I1: High | J1: Notes | K1: Pre-launch Low $ | L1: Pre-launch Mid $ | M1: Pre-Launch High $
A2: ART | B2: Danny Beck fixed deliverables | C2: Pre | D2: 1 | F2: Fixed | G2: 5400 | H2: 5400 | I2: 5400 | J2: Per term sheet fixed cash total | K2: =IF($C2<>"Pre",0,$D2*$G2) | L2: =IF($C2<>"Pre",0,$D2*$H2) | M2: =IF($C2<>"Pre",0,$D2*$I2)
A3: ART | B3: Landing page art + logo (est) | C3: Pre | D3: 1 | F3: Fixed | G3: 300 | H3: 450 | I3: 700 | J3: TBD in definitive agreement | K3: =IF($C3<>"Pre",0,$D3*$G3) | L3: =IF($C3<>"Pre",0,$D3*$H3) | M3: =IF($C3<>"Pre",0,$D3*$I3)
A4: ART | B4: Success bonus (conditional) | C4: Post | D4: 1 | F4: Conditional | G4: 0 | H4: 2000 | I4: 2000 | J4: Only if KS >= $75k gross | K4: =IF($C4<>"Pre",0,$D4*$G4) | L4: =IF($C4<>"Pre",0,$D4*$H4) | M4: =IF($C4<>"Pre",0,$D4*$I4)
A5: LEGAL | B5: Contract/legal review | C5: Pre | D5: 1 | F5: Fixed | G5: 1500 | H5: 2250 | I5: 2250 | J5: UpCounsel quotes $1,500-2,250 for licensing/work-for-hire agreement (Drew's attorney drafts; Danny's $750 stipend covers his attorney's review) | K5: =IF($C5<>"Pre",0,$D5*$G5) | L5: =IF($C5<>"Pre",0,$D5*$H5) | M5: =IF($C5<>"Pre",0,$D5*$I5)
A6: DESIGN | B6: Prototype Decks | C6: Pre | D6: 1 | F6: Fixed | G6: 255 | H6: 255 | I6: 360 | J6: Icons deck + 5 promo decks @ $30 ea for blind playtests/influencers | K6: =IF($C6<>"Pre",0,$D6*$G6) | L6: =IF($C6<>"Pre",0,$D6*$H6) | M6: =IF($C6<>"Pre",0,$D6*$I6)
A7: DESIGN | B7: Rulebook layout | C7: Pre | D7: 1 | F7: Fixed | G7: 800 | H7: 1500 | I7: 2500 | J7: InDesign package + print PDF | K7: =IF($C7<>"Pre",0,$D7*$G7) | L7: =IF($C7<>"Pre",0,$D7*$H7) | M7: =IF($C7<>"Pre",0,$D7*$I7)
A8: EDITOR | B8: Rulebook edit | C8: Pre | D8: 1 | F8: Fixed | G8: 300 | H8: 900 | I8: 2000 | J8: Copyedit vs developmental | K8: =IF($C8<>"Pre",0,$D8*$G8) | L8: =IF($C8<>"Pre",0,$D8*$H8) | M8: =IF($C8<>"Pre",0,$D8*$I8)
A9: MARKETING | B9: Paid ads total | C9: During | D9: 1 | F9: Variable | G9: 3000 | H9: 6000 | I9: 10000 | J9: Range from launch plan | K9: =IF($C9<>"Pre",0,$D9*$G9) | L9: =IF($C9<>"Pre",0,$D9*$H9) | M9: =IF($C9<>"Pre",0,$D9*$I9)
A10: MARKETING | B10: Influencers/previewers | C10: Pre | D10: 1 | F10: Variable | G10: 0 | H10: 500 | I10: 2000 | J10: Review copies + fees | K10: =IF($C10<>"Pre",0,$D10*$G10) | L10: =IF($C10<>"Pre",0,$D10*$H10) | M10: =IF($C10<>"Pre",0,$D10*$I10)
A11: CONTENT | B11: Photography | C11: Pre | D11: 1 | F11: Fixed | G11: 200 | H11: 500 | I11: 1000 | J11: Product shots for KS page | K11: =IF($C11<>"Pre",0,$D11*$G11) | L11: =IF($C11<>"Pre",0,$D11*$H11) | M11: =IF($C11<>"Pre",0,$D11*$I11)
A12: CONTENT | B12: Video/trailer | C12: Pre | D12: 1 | F12: Fixed | G12: 0 | H12: 800 | I12: 3000 | J12: DIY vs hired | K12: =IF($C12<>"Pre",0,$D12*$G12) | L12: =IF($C12<>"Pre",0,$D12*$H12) | M12: =IF($C12<>"Pre",0,$D12*$I12)
A13: WEB | B13: Domain | C13: Pre | D13: 1 | F13: Fixed | G13: 15 | H13: 20 | I13: 25 | J13: Annual | K13: =IF($C13<>"Pre",0,$D13*$G13) | L13: =IF($C13<>"Pre",0,$D13*$H13) | M13: =IF($C13<>"Pre",0,$D13*$I13) | P13: "Shill bidders" to make day one pop.
A14: WEB | B14: Website hosting/platform | C14: Pre | D14: 3 | F14: Fixed | G14: 10 | H14: 20 | I14: 30 | J14: Monthly x 12 | K14: =IF($C14<>"Pre",0,$D14*$G14) | L14: =IF($C14<>"Pre",0,$D14*$H14) | M14: =IF($C14<>"Pre",0,$D14*$I14)
A15: WEB | B15: Landing page tool | C15: Pre | D15: 4 | F15: Fixed | G15: 0 | H15: 15 | I15: 30 | J15: Could be included with site/email tool | K15: =IF($C15<>"Pre",0,$D15*$G15) | L15: =IF($C15<>"Pre",0,$D15*$H15) | M15: =IF($C15<>"Pre",0,$D15*$I15)
A16: EMAIL | B16: Email platform | C16: Pre | D16: 3 | F16: Fixed | G16: 0 | H16: 20 | I16: 60 | J16: Scales with list size | K16: =IF($C16<>"Pre",0,$D16*$G16) | L16: =IF($C16<>"Pre",0,$D16*$H16) | M16: =IF($C16<>"Pre",0,$D16*$I16)
A17: MARKETING | B17: Giveaway/prize + shipping (smoke test) | C17: Pre | D17: 1 | F17: Fixed | G17: 200 | H17: 200 | I17: 200 | J17: Need something to juice the smoke test | K17: =IF($C17<>"Pre",0,$D17*$G17) | L17: =IF($C17<>"Pre",0,$D17*$H17) | M17: =IF($C17<>"Pre",0,$D17*$I17)
A18: BUFFER | B18: In case shit | C18: Pre | D18: 1 | F18: Fixed | G18: 1500 | H18: 1500 | I18: 1500 | J18: In Case Shit | K18: =IF($C18<>"Pre",0,$D18*$G18) | L18: =IF($C18<>"Pre",0,$D18*$H18) | M18: =IF($C18<>"Pre",0,$D18*$I18)
A19: CONTENT | B19: Video Capture kit | C19: Pre | D19: 1 | F19: Fixed | G19: 150 | H19: 350 | I19: 900 | J19: Audio/Light/Tripod | K19: =IF($C19<>"Pre",0,$D19*$G19) | L19: =IF($C19<>"Pre",0,$D19*$H19) | M19: =IF($C19<>"Pre",0,$D19*$I19)
A20: CONTENT | B20: Kickstarter Video Support | C20: Pre | D20: 1 | F20: Fixed | G20: 1000 | H20: 1500 | I20: 3000 | K20: =IF($C20<>"Pre",0,$D20*$G20) | L20: =IF($C20<>"Pre",0,$D20*$H20) | M20: =IF($C20<>"Pre",0,$D20*$I20)
A21: SOFTWARE | B21: Claude Max (AI project support) | C21: Pre | D21: 1 | E21: 100 | F21: Fixed | G21: 700 | H21: 700 | I21: 700 | J21: $100/mo x 7 months (Feb-Aug) | K21: =IF($C21<>"Pre",0,$D21*$G21) | L21: =IF($C21<>"Pre",0,$D21*$H21) | M21: =IF($C21<>"Pre",0,$D21*$I21)
A22: INSURANCE | B22: Commercial General Liability | C22: Post | D22: 1 | F22: Variable | G22: 400 | H22: 1200 | I22: 3000 | K22: =IF($C22<>"Pre",0,$D22*$G22) | L22: =IF($C22<>"Pre",0,$D22*$H22) | M22: =IF($C22<>"Pre",0,$D22*$I22)
A24: Current Sum | K24: =SUM(K2:K22) | L24: =SUM(L2:L22) | M24: =SUM(M2:M22)

Sheet Inputs
A1: INPUTS
A2: Item | B2: Cost/percentage
A3: Pre-launch budget | B3: 15000
A4: Campaign Marketing | B4: 4000
A5: Avg pledge per backer | B5: 30
A6: Avg add-on per backer | B6: 3
A7: Shipping charged per backer | B7: 10
A8: Shipping cost per backer | B8: 8
A10: Kickstarter platform fee | B10: 0.05
A11: Payment processing fee | B11: 0.035
A12: Refunds/failed charges | B12: 0.02
A14: Manufacturing Cost per unit | B14: 8.13
A15: Freight cost per unit | B15: 2
A16: Fulfillment pick/pack per order | B16: 4
... A29: Bulk Sale Probability | B29: 0.5

Sheet Mfg Comparison
A1: MANUFACTURER PRICING (per unit, base game)
A2: Manufacturer | B2: MOQ | C2: Price @500 | D2: Price @1,000 | E2: Price @2,000 | F2: Status | G2: Notes
A3: HiCreate Games (Leah) | B3: 500 | C3: 5.1 | D3: 3.66 | E3: 3.06 | F3: Quoted | G3: leah@hicreategames.com
A4: Vart Games (Jenny) | B4: 500 | F4: Replied - pricing TBD | G4: jenny.yue@vartgames.com
A5: Delano | B5: 2000 | F5: Replied - MOQ too high? | G5: US manufacturer
A6: Longpack | F6: Pending | G6: Sent RFQ Feb 23
A7: AGR Priority | B7: 500 | C7: 7.65 | D7: 5.31 | E7: 4.23 | F7: Quoted | G7: MOQ 500
A8: (Add manufacturer)
A10: Deluxe markup over base price | B10: 0.8 | C10: Adjust this assumption as needed
A13: ORDER SCENARIO
B14: Base Units | C14: Deluxe Units | D14: Total Units
A15: Your order plan | B15: 1000 | C15: 500 | D15: =B15+C15
A18: COST COMPARISON BY MANUFACTURER
A19: Manufacturer | B19: Base $/unit | C19: Deluxe $/unit | D19: Base Total | E19: Deluxe Total | F19: Grand Total | G19: Avg $/unit | H19: vs Current Budget
A20: =A3 | B20: =IF(B15>=2000,E3,IF(B15>=1000,D3,C3)) | C20: =IF(C15>=2000,E3,IF(C15>=1000,D3,C3))*(1+$B$10) | D20: =B20*$B$15 | E20: =C20*$C$15 | F20: =D20+E20 | G20: =IF($D$15=0,0,F20/$D$15) | H20: =G20-Inputs!$B$14
A21: =A4 | B21: =IF(B15>=2000,E4,IF(B15>=1000,D4,C4)) | C21: =IF(C15>=2000,E4,IF(C15>=1000,D4,C4))*(1+$B$10) | D21: =B21*$B$15 | E21: =C21*$C$15 | F21: =D21+E21 | G21: =IF($D$15=0,0,F21/$D$15) | H21: =G21-Inputs!$B$14
A22: =A5 | B22: =IF(B15>=2000,E5,IF(B15>=1000,D5,C5)) | C22: =IF(C15>=2000,E5,IF(C15>=1000,D5,C5))*(1+$B$10) | D22: =B22*$B$15 | E22: =C22*$C$15 | F22: =D22+E22 | G22: =IF($D$15=0,0,F22/$D$15) | H22: =G22-Inputs!$B$14
A23: =A6 | B23: =IF(B15>=2000,E6,IF(B15>=1000,D6,C6)) | C23: =IF(C15>=2000,E6,IF(C15>=1000,D6,C6))*(1+$B$10) | D23: =B23*$B$15 | E23: =C23*$C$15 | F23: =D23+E23 | G23: =IF($D$15=0,0,F23/$D$15) | H23: =G23-Inputs!$B$14
A24: =A7 | B24: =IF(B15>=2000,E7,IF(B15>=1000,D7,C7)) | C24: =IF(C15>=2000,E7,IF(C15>=1000,D7,C7))*(1+$B$10) | D24: =B24*$B$15 | E24: =C24*$C$15 | F24: =D24+E24 | G24: =IF($D$15=0,0,F24/$D$15) | H24: =G24-Inputs!$B$14
A25: =A8 | B25: =IF(B15>=2000,E8,IF(B15>=1000,D8,C8)) | C25: =IF(C15>=2000,E8,IF(C15>=1000,D8,C8))*(1+$B$10) | D25: =B25*$B$15 | E25: =C25*$C$15 | F25: =D25+E25 | G25: =IF($D$15=0,0,F25/$D$15) | H25: =G25-Inputs!$B$14
A28: PROFIT IMPACT AT DIFFERENT KS FUNDING LEVELS (vs current $6.50/unit assumption)
A29: KS Gross Funding | B29: Backers | C29: =A20 | D29: =A21 | E29: =A22 | F29: =A23 | G29: =A24 | H29: =A25
A30: 25000 | B30: =A30/(Inputs!$B$5+Inputs!$B$6) | C30: =IF(G20=0,"—",(Inputs!$B$14-G20)*B30) | D30: =IF(G21=0,"—",(Inputs!$B$14-G21)*B30) | E30: =IF(G22=0,"—",(Inputs!$B$14-G22)*B30) | F30: =IF(G23=0,"—",(Inputs!$B$14-G23)*B30) | G30: =IF(G24=0,"—",(Inputs!$B$14-G24)*B30) | H30: =IF(G25=0,"—",(Inputs!$B$14-G25)*B30)
A31: 30000 | B31: =A31/(Inputs!$B$5+Inputs!$B$6) | C31: =IF(G20=0,"—",(Inputs!$B$14-G20)*B31) | D31: =IF(G21=0,"—",(Inputs!$B$14-G21)*B31) | E31: =IF(G22=0,"—",(Inputs!$B$14-G22)*B31) | F31: =IF(G23=0,"—",(Inputs!$B$14-G23)*B31) | G31: =IF(G24=0,"—",(Inputs!$B$14-G24)*B31) | H31: =IF(G25=0,"—",(Inputs!$B$14-G25)*B31)
A32: 40000 | B32: =A32/(Inputs!$B$5+Inputs!$B$6) | C32: =IF(G20=0,"—",(Inputs!$B$14-G20)*B32) | D32: =IF(G21=0,"—",(Inputs!$B$14-G21)*B32) | E32: =IF(G22=0,"—",(Inputs!$B$14-G22)*B32) | F32: =IF(G23=0,"—",(Inputs!$B$14-G23)*B32) | G32: =IF(G24=0,"—",(Inputs!$B$14-G24)*B32) | H32: =IF(G25=0,"—",(Inputs!$B$14-G25)*B32)
A33: 49500 | B33: =A33/(Inputs!$B$5+Inputs!$B$6) | C33: =IF(G20=0,"—",(Inputs!$B$14-G20)*B33) | D33: =IF(G21=0,"—",(Inputs!$B$14-G21)*B33) | E33: =IF(G22=0,"—",(Inputs!$B$14-G22)*B33) | F33: =IF(G23=0,"—",(Inputs!$B$14-G23)*B33) | G33: =IF(G24=0,"—",(Inputs!$B$14-G24)*B33) | H33: =IF(G25=0,"—",(Inputs!$B$14-G25)*B33)
A34: 60000 | B34: =A34/(Inputs!$B$5+Inputs!$B$6) | C34: =IF(G20=0,"—",(Inputs!$B$14-G20)*B34) | D34: =IF(G21=0,"—",(Inputs!$B$14-G21)*B34) | E34: =IF(G22=0,"—",(Inputs!$B$14-G22)*B34) | F34: =IF(G23=0,"—",(Inputs!$B$14-G23)*B34) | G34: =IF(G24=0,"—",(Inputs!$B$14-G24)*B34) | H34: =IF(G25=0,"—",(Inputs!$B$14-G25)*B34)
A35: 75000 | B35: =A35/(Inputs!$B$5+Inputs!$B$6) | C35: =IF(G20=0,"—",(Inputs!$B$14-G20)*B35) | D35: =IF(G21=0,"—",(Inputs!$B$14-G21)*B35) | E35: =IF(G22=0,"—",(Inputs!$B$14-G22)*B35) | F35: =IF(G23=0,"—",(Inputs!$B$14-G23)*B35) | G35: =IF(G24=0,"—",(Inputs!$B$14-G24)*B35) | H35: =IF(G25=0,"—",(Inputs!$B$14-G25)*B35)
A36: 100000 | B36: =A36/(Inputs!$B$5+Inputs!$B$6) | C36: =IF(G20=0,"—",(Inputs!$B$14-G20)*B36) | D36: =IF(G21=0,"—",(Inputs!$B$14-G21)*B36) | E36: =IF(G22=0,"—",(Inputs!$B$14-G22)*B36) | F36: =IF(G23=0,"—",(Inputs!$B$14-G23)*B36) | G36: =IF(G24=0,"—",(Inputs!$B$14-G24)*B36) | H36: =IF(G25=0,"—",(Inputs!$B$14-G25)*B36)
A37: 150000 | B37: =A37/(Inputs!$B$5+Inputs!$B$6) | C37: =IF(G20=0,"—",(Inputs!$B$14-G20)*B37) | D37: =IF(G21=0,"—",(Inputs!$B$14-G21)*B37) | E37: =IF(G22=0,"—",(Inputs!$B$14-G22)*B37) | F37: =IF(G23=0,"—",(Inputs!$B$14-G23)*B37) | G37: =IF(G24=0,"—",(Inputs!$B$14-G24)*B37) | H37: =IF(G25=0,"—",(Inputs!$B$14-G25)*B37)
A38: 200000 | B38: =A38/(Inputs!$B$5+Inputs!$B$6) | C38: =IF(G20=0,"—",(Inputs!$B$14-G20)*B38) | D38: =IF(G21=0,"—",(Inputs!$B$14-G21)*B38) | E38: =IF(G22=0,"—",(Inputs!$B$14-G22)*B38) | F38: =IF(G23=0,"—",(Inputs!$B$14-G23)*B38) | G38: =IF(G24=0,"—",(Inputs!$B$14-G24)*B38) | H38: =IF(G25=0,"—",(Inputs!$B$14-G25)*B38)
A39: Positive = savings vs current budget assumption. Negative = more expensive.
A41: QUICK REFERENCE
A42: Current budget mfg cost/unit | B42: =Inputs!B14 | C42: (from Inputs sheet)
A43: Budget mfg target | B43: < $8.00/unit
A44: To update Scenarios sheet: | B44: Change Inputs!B14 to the chosen manufacturer's avg $/unit

Sheet Organic Growth Model
A1: KICKSTARTER ORGANIC DISCOVERY MODEL
A2: Based on Crowdfunding Nerds analysis: ~40-43% of tabletop campaign revenue comes from KS organic discovery.
A3: Organic discovery scales with campaign momentum — stronger early funding = more algorithm visibility.
A5: ASSUMPTIONS (adjust blue cells)
A6: Avg pledge (from Inputs) | B6: =Inputs!B5+Inputs!B6 | C6: Pledge + add-ons
A7: Organic % — small campaign (<$25K) | B7: 0.2 | C7: KS browse/search, lower algorithm boost
A8: Organic % — mid campaign ($25K-$75K) | B8: 0.35 | C8: Category ranking + some featuring
A9: Organic % — strong campaign ($75K-$150K) | B9: 0.4 | C9: Projects We Love territory
A10: Organic % — breakout campaign ($150K+) | B10: 0.43 | C10: Max organic ceiling per research
A11: "Projects We Love" bonus | B11: 0.05 | C11: Extra organic boost if badge awarded
A12: Got "Projects We Love"? | B12: No | C12: Change to "Yes" if awarded
A14: FROM YOUR MARKETING → TOTAL BACKERS (with organic growth)
A15: Creator-Driven Backers | B15: Creator $ Revenue | C15: Organic % Applied | D15: Organic Backers | E15: Total Backers | F15: Total Gross $ | G15: Effective Multiplier | H15: Profit Impact vs No Organic
A16: 200 | B16: =A16*$B$6 | C16: =IF($B$12="Yes",$B$11,0)+IF(B16<25000,$B$7,IF(B16<75000,$B$8,IF(B16<150000,$B$9,$B$10))) | D16: =ROUND(A16*(C16/(1-C16)),0) | E16: =A16+D16 | F16: =E16*$B$6 | G16: =IF(A16=0,0,E16/A16) | H16: =D16*($B$6*(1-Inputs!$B$10-Inputs!$B$11-Inputs!$B$12)-(Inputs!$B$14+Inputs!$B$15+Inputs!$B$16+Inputs!$B$17))
A17: 300 | B17: =A17*$B$6 | C17: =IF($B$12="Yes",$B$11,0)+IF(B17<25000,$B$7,IF(B17<75000,$B$8,IF(B17<150000,$B$9,$B$10))) | D17: =ROUND(A17*(C17/(1-C17)),0) | E17: =A17+D17 | F17: =E17*$B$6 | G17: =IF(A17=0,0,E17/A17) | H17: =D17*($B$6*(1-Inputs!$B$10-Inputs!$B$11-Inputs!$B$12)-(Inputs!$B$14+Inputs!$B$15+Inputs!$B$16+Inputs!$B$17))
A18: 400 | B18: =A18*$B$6 | C18: =IF($B$12="Yes",$B$11,0)+IF(B18<25000,$B$7,IF(B18<75000,$B$8,IF(B18<150000,$B$9,$B$10))) | D18: =ROUND(A18*(C18/(1-C18)),0) | E18: =A18+D18 | F18: =E18*$B$6 | G18: =IF(A18=0,0,E18/A18) | H18: =D18*($B$6*(1-Inputs!$B$10-Inputs!$B$11-Inputs!$B$12)-(Inputs!$B$14+Inputs!$B$15+Inputs!$B$16+Inputs!$B$17))
A19: 500 | B19: =A19*$B$6 | C19: =IF($B$12="Yes",$B$11,0)+IF(B19<25000,$B$7,IF(B19<75000,$B$8,IF(B19<150000,$B$9,$B$10))) | D19: =ROUND(A19*(C19/(1-C19)),0) | E19: =A19+D19 | F19: =E19*$B$6 | G19: =IF(A19=0,0,E19/A19) | H19: =D19*($B$6*(1-Inputs!$B$10-Inputs!$B$11-Inputs!$B$12)-(Inputs!$B$14+Inputs!$B$15+Inputs!$B$16+Inputs!$B$17))
A20: 600 | B20: =A20*$B$6 | C20: =IF($B$12="Yes",$B$11,0)+IF(B20<25000,$B$7,IF(B20<75000,$B$8,IF(B20<150000,$B$9,$B$10))) | D20: =ROUND(A20*(C20/(1-C20)),0) | E20: =A20+D20 | F20: =E20*$B$6 | G20: =IF(A20=0,0,E20/A20) | H20: =D20*($B$6*(1-Inputs!$B$10-Inputs!$B$11-Inputs!$B$12)-(Inputs!$B$14+Inputs!$B$15+Inputs!$B$16+Inputs!$B$17))
A21: 750 | B21: =A21*$B$6 | C21: =IF($B$12="Yes",$B$11,0)+IF(B21<25000,$B$7,IF(B21<75000,$B$8,IF(B21<150000,$B$9,$B$10))) | D21: =ROUND(A21*(C21/(1-C21)),0) | E21: =A21+D21 | F21: =E21*$B$6 | G21: =IF(A21=0,0,E21/A21) | H21: =D21*($B$6*(1-Inputs!$B$10-Inputs!$B$11-Inputs!$B$12)-(Inputs!$B$14+Inputs!$B$15+Inputs!$B$16+Inputs!$B$17))
A22: 900 | B22: =A22*$B$6 | C22: =IF($B$12="Yes",$B$11,0)+IF(B22<25000,$B$7,IF(B22<75000,$B$8,IF(B22<150000,$B$9,$B$10))) | D22: =ROUND(A22*(C22/(1-C22)),0) | E22: =A22+D22 | F22: =E22*$B$6 | G22: =IF(A22=0,0,E22/A22) | H22: =D22*($B$6*(1-Inputs!$B$10-Inputs!$B$11-Inputs!$B$12)-(Inputs!$B$14+Inputs!$B$15+Inputs!$B$16+Inputs!$B$17))
A23: 1000 | B23: =A23*$B$6 | C23: =IF($B$12="Yes",$B$11,0)+IF(B23<25000,$B$7,IF(B23<75000,$B$8,IF(B23<150000,$B$9,$B$10))) | D23: =ROUND(A23*(C23/(1-C23)),0) | E23: =A23+D23 | F23: =E23*$B$6 | G23: =IF(A23=0,0,E23/A23) | H23: =D23*($B$6*(1-Inputs!$B$10-Inputs!$B$11-Inputs!$B$12)-(Inputs!$B$14+Inputs!$B$15+Inputs!$B$16+Inputs!$B$17))
A24: 1200 | B24: =A24*$B$6 | C24: =IF($B$12="Yes",$B$11,0)+IF(B24<25000,$B$7,IF(B24<75000,$B$8,IF(B24<150000,$B$9,$B$10))) | D24: =ROUND(A24*(C24/(1-C24)),0) | E24: =A24+D24 | F24: =E24*$B$6 | G24: =IF(A24=0,0,E24/A24) | H24: =D24*($B$6*(1-Inputs!$B$10-Inputs!$B$11-Inputs!$B$12)-(Inputs!$B$14+Inputs!$B$15+Inputs!$B$16+Inputs!$B$17))
A25: 1500 | B25: =A25*$B$6 | C25: =IF($B$12="Yes",$B$11,0)+IF(B25<25000,$B$7,IF(B25<75000,$B$8,IF(B25<150000,$B$9,$B$10))) | D25: =ROUND(A25*(C25/(1-C25)),0) | E25: =A25+D25 | F25: =E25*$B$6 | G25: =IF(A25=0,0,E25/A25) | H25: =D25*($B$6*(1-Inputs!$B$10-Inputs!$B$11-Inputs!$B$12)-(Inputs!$B$14+Inputs!$B$15+Inputs!$B$16+Inputs!$B$17))
A26: 2000 | B26: =A26*$B$6 | C26: =IF($B$12="Yes",$B$11,0)+IF(B26<25000,$B$7,IF(B26<75000,$B$8,IF(B26<150000,$B$9,$B$10))) | D26: =ROUND(A26*(C26/(1-C26)),0) | E26: =A26+D26 | F26: =E26*$B$6 | G26: =IF(A26=0,0,E26/A26) | H26: =D26*($B$6*(1-Inputs!$B$10-Inputs!$B$11-Inputs!$B$12)-(Inputs!$B$14+Inputs!$B$15+Inputs!$B$16+Inputs!$B$17))
A27: 2500 | B27: =A27*$B$6 | C27: =IF($B$12="Yes",$B$11,0)+IF(B27<25000,$B$7,IF(B27<75000,$B$8,IF(B27<150000,$B$9,$B$10))) | D27: =ROUND(A27*(C27/(1-C27)),0) | E27: =A27+D27 | F27: =E27*$B$6 | G27: =IF(A27=0,0,E27/A27) | H27: =D27*($B$6*(1-Inputs!$B$10-Inputs!$B$11-Inputs!$B$12)-(Inputs!$B$14+Inputs!$B$15+Inputs!$B$16+Inputs!$B$17))
A28: 3000 | B28: =A28*$B$6 | C28: =IF($B$12="Yes",$B$11,0)+IF(B28<25000,$B$7,IF(B28<75000,$B$8,IF(B28<150000,$B$9,$B$10))) | D28: =ROUND(A28*(C28/(1-C28)),0) | E28: =A28+D28 | F28: =E28*$B$6 | G28: =IF(A28=0,0,E28/A28) | H28: =D28*($B$6*(1-Inputs!$B$10-Inputs!$B$11-Inputs!$B$12)-(Inputs!$B$14+Inputs!$B$15+Inputs!$B$16+Inputs!$B$17))
A31: DANNY FUNNEL + YOUR MARKETING → PROJECTED ORGANIC GROWTH
A32: Source | B32: Backers (creator) | C32: Organic Boost | D32: Total Backers | E32: Gross Funding | F32: vs Budget Break-even
A33: Current baseline | B33: =Scenarios!M25 | C33: =IF($B$12="Yes",$B$11,0)+IF(B33*$B$6<25000,$B$7,IF(B33*$B$6<75000,$B$8,IF(B33*$B$6<150000,$B$9,$B$10))) | D33: =ROUND(B33/(1-C33),0) | E33: =D33*$B$6 | F33: =E33-40000
A34: Moderate growth | B34: =Scenarios!M26 | C34: =IF($B$12="Yes",$B$11,0)+IF(B34*$B$6<25000,$B$7,IF(B34*$B$6<75000,$B$8,IF(B34*$B$6<150000,$B$9,$B$10))) | D34: =ROUND(B34/(1-C34),0) | E34: =D34*$B$6 | F34: =E34-40000
A35: Strong pre-launch | B35: =Scenarios!M27 | C35: =IF($B$12="Yes",$B$11,0)+IF(B35*$B$6<25000,$B$7,IF(B35*$B$6<75000,$B$8,IF(B35*$B$6<150000,$B$9,$B$10))) | D35: =ROUND(B35/(1-C35),0) | E35: =D35*$B$6 | F35: =E35-40000
A36: Aggressive marketing | B36: =Scenarios!M28 | C36: =IF($B$12="Yes",$B$11,0)+IF(B36*$B$6<25000,$B$7,IF(B36*$B$6<75000,$B$8,IF(B36*$B$6<150000,$B$9,$B$10))) | D36: =ROUND(B36/(1-C36),0) | E36: =D36*$B$6 | F36: =E36-40000
A37: Danny leverage play | B37: =Scenarios!M29 | C37: =IF($B$12="Yes",$B$11,0)+IF(B37*$B$6<25000,$B$7,IF(B37*$B$6<75000,$B$8,IF(B37*$B$6<150000,$B$9,$B$10))) | D37: =ROUND(B37/(1-C37),0) | E37: =D37*$B$6 | F37: =E37-40000
A38: Home run | B38: =Scenarios!M30 | C38: =IF($B$12="Yes",$B$11,0)+IF(B38*$B$6<25000,$B$7,IF(B38*$B$6<75000,$B$8,IF(B38*$B$6<150000,$B$9,$B$10))) | D38: =ROUND(B38/(1-C38),0) | E38: =D38*$B$6 | F38: =E38-40000
A40: Break-even target: ~$35K-$40K gross KS funding (~1,100 backers)
A42: TYPICAL KS FUNDING CURVE (% of total by phase)
A43: Campaign Phase | B43: Days | C43: % of Total Funding | D43: Cumulative % | E43: Notes
A44: Launch day (Day 1) | B44: 1 | C44: 0.2 | D44: =SUM($C$44:C44) | E44: Biggest single day — email list + followers convert
A45: Early momentum (Days 2-3) | B45: 2 | C45: 0.12 | D45: =SUM($C$44:C45) | E45: Word of mouth, social shares
A46: First week (Days 4-7) | B46: 4 | C46: 0.08 | D46: =SUM($C$44:C46) | E46: Algorithm starts noticing if funded fast
...

Sheet Scenarios
A1: Gross funding | B1: Backers (est) | C1: Gross rev / backer | D1: Fees (KS+proc+refunds) | E1: Net after fees | F1: Variable Cost / Backer | G1: Total Variable Costs | H1: Contingency Reserve | I1: Bonus Triggered? | J1: Profit after all (incl prelaunch) with MOQ | K1: ROI on prelaunch | L1: Worth it? | M1: Units Needed | N1: Units Produced (MOQ) | O1: Leftover Units | P1: Extra MOQ cost (mfg+freight) | Q1: Salvage Revenue (bulk sale)
A2: 25000 | B2: =A2/$C$2 | C2: =Inputs!$B$5+Inputs!$B$6 | D2: =A2*(Inputs!$B$10+Inputs!$B$11+Inputs!$B$12) | E2: =A2-D2 | F2: =Inputs!$B$14 + Inputs!$B$15 + IF($B2<=Inputs!$B$24, 0, Inputs!$B$16) + Inputs!$B$17 | G2: =$B2*$F2 | H2: =Inputs!$B$19*G2 | I2: =IF(A2>=Inputs!$B$22, Inputs!$B$21, 0) | J2: =E2 - G2 - H2 - Inputs!$B$3 - Inputs!$B$4 - I2 - P2 + Q2 | K2: =J2 / Inputs!$B$3 | L2: =IF(J2>0,"YES","NO") | M2: =ROUNDUP($B2 * Inputs!$B$27, 0) | N2: =MAX(M2, Inputs!$B$26) | O2: =MAX(0, N2 - M2) | P2: =O2 * (Inputs!$B$14 + Inputs!$B$15) | Q2: =O2 * (Inputs!$B$14 + Inputs!$B$15) * (1 + Inputs!$B$28) * IF(Inputs!$B$29="",1,Inputs!$B$29)
A3: 30000 | B3: =A3/$C$2 | C3: =Inputs!$B$5+Inputs!$B$6 | D3: =A3*(Inputs!$B$10+Inputs!$B$11+Inputs!$B$12) | E3: =A3-D3 | F3: =Inputs!$B$14 + Inputs!$B$15 + IF($B3<=Inputs!$B$24, 0, Inputs!$B$16) + Inputs!$B$17 | G3: =$B3*$F3 | H3: =Inputs!$B$19*G3 | I3: =IF(A3>=Inputs!$B$22, Inputs!$B$21, 0) | J3: =E3 - G3 - H3 - Inputs!$B$3 - Inputs!$B$4 - I3 - P3 + Q3 | K3: =J3 / Inputs!$B$3 | L3: =IF(J3>0,"YES","NO") | M3: =ROUNDUP($B3 * Inputs!$B$27, 0) | N3: =MAX(M3, Inputs!$B$26) | O3: =MAX(0, N3 - M3) | P3: =O3 * (Inputs!$B$14 + Inputs!$B$15) | Q3: =O3 * (Inputs!$B$14 + Inputs!$B$15) * (1 + Inputs!$B$28) * IF(Inputs!$B$29="",1,Inputs!$B$29)
A4: 40000 | B4: =A4/$C4 | C4: =Inputs!$B$5+Inputs!$B$6 | D4: =A4*(Inputs!$B$10+Inputs!$B$11+Inputs!$B$12) | E4: =A4-D4 | F4: =Inputs!$B$14 + Inputs!$B$15 + IF($B4<=Inputs!$B$24, 0, Inputs!$B$16) + Inputs!$B$17 | G4: =$B4*$F4 | H4: =Inputs!$B$19*G4 | I4: =IF(A4>=Inputs!$B$22, Inputs!$B$21, 0) | J4: =E4 - G4 - H4 - Inputs!$B$3 - Inputs!$B$4 - I4 - P4 + Q4 | K4: =J4 / Inputs!$B$3 | L4: =IF(J4>0,"YES","NO") | M4: =ROUNDUP($B4 * Inputs!$B$27, 0) | N4: =MAX(M4, Inputs!$B$26) | O4: =MAX(0, N4 - M4) | P4: =O4 * (Inputs!$B$14 + Inputs!$B$15) | Q4: =O4 * (Inputs!$B$14 + Inputs!$B$15) * (1 + Inputs!$B$28) * IF(Inputs!$B$29="",1,Inputs!$B$29)
A5: 49500 | B5: =A5/$C5 | C5: =Inputs!$B$5+Inputs!$B$6 | D5: =A5*(Inputs!$B$10+Inputs!$B$11+Inputs!$B$12) | E5: =A5-D5 | F5: =Inputs!$B$14 + Inputs!$B$15 + IF($B5<=Inputs!$B$24, 0, Inputs!$B$16) + Inputs!$B$17 | G5: =$B5*$F5 | H5: =Inputs!$B$19*G5 | I5: =IF(A5>=Inputs!$B$22, Inputs!$B$21, 0) | J5: =E5 - G5 - H5 - Inputs!$B$3 - Inputs!$B$4 - I5 - P5 + Q5 | K5: =J5 / Inputs!$B$3 | L5: =IF(J5>0,"YES","NO") | M5: =ROUNDUP($B5 * Inputs!$B$27, 0) | N5: =MAX(M5, Inputs!$B$26) | O5: =MAX(0, N5 - M5) | P5: =O5 * (Inputs!$B$14 + Inputs!$B$15) | Q5: =O5 * (Inputs!$B$14 + Inputs!$B$15) * (1 + Inputs!$B$28) * IF(Inputs!$B$29="",1,Inputs!$B$29)
A6: 60000 | B6: =A6/$C6 | C6: =Inputs!$B$5+Inputs!$B$6 | D6: =A6*(Inputs!$B$10+Inputs!$B$11+Inputs!$B$12) | E6: =A6-D6 | F6: =Inputs!$B$14 + Inputs!$B$15 + IF($B6<=Inputs!$B$24, 0, Inputs!$B$16) + Inputs!$B$17 | G6: =$B6*$F6 | H6: =Inputs!$B$19*G6 | I6: =IF(A6>=Inputs!$B$22, Inputs!$B$21, 0) | J6: =E6 - G6 - H6 - Inputs!$B$3 - Inputs!$B$4 - I6 - P6 + Q6 | K6: =J6 / Inputs!$B$3 | L6: =IF(J6>0,"YES","NO") | M6: =ROUNDUP($B6 * Inputs!$B$27, 0) | N6: =MAX(M6, Inputs!$B$26) | O6: =MAX(0, N6 - M6) | P6: =O6 * (Inputs!$B$14 + Inputs!$B$15) | Q6: =O6 * (Inputs!$B$14 + Inputs!$B$15) * (1 + Inputs!$B$28) * IF(Inputs!$B$29="",1,Inputs!$B$29)
A7: 75000 | B7: =A7/$C7 | C7: =Inputs!$B$5+Inputs!$B$6 | D7: =A7*(Inputs!$B$10+Inputs!$B$11+Inputs!$B$12) | E7: =A7-D7 | F7: =Inputs!$B$14 + Inputs!$B$15 + IF($B7<=Inputs!$B$24, 0, Inputs!$B$16) + Inputs!$B$17 | G7: =$B7*$F7 | H7: =Inputs!$B$19*G7 | I7: =IF(A7>=Inputs!$B$22, Inputs!$B$21, 0) | J7: =E7 - G7 - H7 - Inputs!$B$3 - Inputs!$B$4 - I7 - P7 + Q7 | K7: =J7 / Inputs!$B$3 | L7: =IF(J7>0,"YES","NO") | M7: =ROUNDUP($B7 * Inputs!$B$27, 0) | N7: =MAX(M7, Inputs!$B$26) | O7: =MAX(0, N7 - M7) | P7: =O7 * (Inputs!$B$14 + Inputs!$B$15) | Q7: =O7 * (Inputs!$B$14 + Inputs!$B$15) * (1 + Inputs!$B$28) * IF(Inputs!$B$29="",1,Inputs!$B$29)
A8: 100000 | B8: =A8/$C8 | C8: =Inputs!$B$5+Inputs!$B$6 | D8: =A8*(Inputs!$B$10+Inputs!$B$11+Inputs!$B$12) | E8: =A8-D8 | F8: =Inputs!$B$14 + Inputs!$B$15 + IF($B8<=Inputs!$B$24, 0, Inputs!$B$16) + Inputs!$B$17 | G8: =$B8*$F8 | H8: =Inputs!$B$19*G8 | I8: =IF(A8>=Inputs!$B$22, Inputs!$B$21, 0) | J8: =E8 - G8 - H8 - Inputs!$B$3 - Inputs!$B$4 - I8 - P8 + Q8 | K8: =J8 / Inputs!$B$3 | L8: =IF(J8>0,"YES","NO") | M8: =ROUNDUP($B8 * Inputs!$B$27, 0) | N8: =MAX(M8, Inputs!$B$26) | O8: =MAX(0, N8 - M8) | P8: =O8 * (Inputs!$B$14 + Inputs!$B$15) | Q8: =O8 * (Inputs!$B$14 + Inputs!$B$15) * (1 + Inputs!$B$28) * IF(Inputs!$B$29="",1,Inputs!$B$29)
A9: 150000 | B9: =A9/$C9 | C9: =Inputs!$B$5+Inputs!$B$6 | D9: =A9*(Inputs!$B$10+Inputs!$B$11+Inputs!$B$12) | E9: =A9-D9 | F9: =Inputs!$B$14 + Inputs!$B$15 + IF($B9<=Inputs!$B$24, 0, Inputs!$B$16) + Inputs!$B$17 | G9: =$B9*$F9 | H9: =Inputs!$B$19*G9 | I9: =IF(A9>=Inputs!$B$22, Inputs!$B$21, 0) | J9: =E9 - G9 - H9 - Inputs!$B$3 - Inputs!$B$4 - I9 - P9 + Q9 | K9: =J9 / Inputs!$B$3 | L9: =IF(J9>0,"YES","NO") | M9: =ROUNDUP($B9 * Inputs!$B$27, 0) | N9: =MAX(M9, Inputs!$B$26) | O9: =MAX(0, N9 - M9) | P9: =O9 * (Inputs!$B$14 + Inputs!$B$15) | Q9: =O9 * (Inputs!$B$14 + Inputs!$B$15) * (1 + Inputs!$B$28) * IF(Inputs!$B$29="",1,Inputs!$B$29)
A10: 200000 | B10: =A10/$C10 | C10: =Inputs!$B$5+Inputs!$B$6 | D10: =A10*(Inputs!$B$10+Inputs!$B$11+Inputs!$B$12) | E10: =A10-D10 | F10: =Inputs!$B$14 + Inputs!$B$15 + IF($B10<=Inputs!$B$24, 0, Inputs!$B$16) + Inputs!$B$17 | G10: =$B10*$F10 | H10: =Inputs!$B$19*G10 | I10: =IF(A10>=Inputs!$B$22, Inputs!$B$21, 0) | J10: =E10 - G10 - H10 - Inputs!$B$3 - Inputs!$B$4 - I10 - P10 + Q10 | K10: =J10 / Inputs!$B$3 | L10: =IF(J10>0,"YES","NO") | M10: =ROUNDUP($B10 * Inputs!$B$27, 0) | N10: =MAX(M10, Inputs!$B$26) | O10: =MAX(0, N10 - M10) | P10: =O10 * (Inputs!$B$14 + Inputs!$B$15) | Q10: =O10 * (Inputs!$B$14 + Inputs!$B$15) * (1 + Inputs!$B$28) * IF(Inputs!$B$29="",1,Inputs!$B$29)
B15: Backers (est) | C15: Shipping Collected Later | D15: Shipping Cost Later | E15: Shipping Surplus/Shortfall | G15: Email List Size | H15: 2000
B16: 625 | C16: =B16*Inputs!$B$7 | D16: =B16*Inputs!$B$8 | E16: =C16-D16 | G16: Email -> Backer Conversion % | H16: 0.01
B17: 1000 | C17: =B17*Inputs!$B$7 | D17: =B17*Inputs!$B$8 | E17: =C17-D17 | G17: KS Followers | H17: 500
B18: 1500 | C18: =B18*Inputs!$B$7 | D18: =B18*Inputs!$B$8 | E18: =C18-D18 | G18: Follower -> Backer Conversion % | H18: 0.5
B19: 1875 | C19: =B19*Inputs!$B$7 | D19: =B19*Inputs!$B$8 | E19: =C19-D19 | G19: Other Sources Backers | H19: 100
B20: 2500 | C20: =B20*Inputs!$B$7 | D20: =B20*Inputs!$B$8 | E20: =C20-D20 | G20: Expected Backers | H20: =H15*H16+H17*H18+H19
B21: 3750 | C21: =B21*Inputs!$B$7 | D21: =B21*Inputs!$B$8 | E21: =C21-D21 | G21: Total Backers over KS Campaign | H21: =H20*1.6
B22: 5000 | C22: =B22*Inputs!$B$7 | D22: =B22*Inputs!$B$8 | E22: =C22-D22
G23: BACKER CONVERSION SCENARIOS
G24: Scenario | H24: Email List | I24: Email Conv % | J24: KS Followers | K24: Follower Conv % | L24: Other Sources | M24: Expected Backers
G25: Current (baseline) | H25: 2000 | I25: 0.01 | J25: 500 | K25: 0.5 | L25: 100 | M25: =H25*I25+J25*K25+L25
G26: Moderate growth | H26: 5000 | I26: 0.03 | J26: 1000 | K26: 0.4 | L26: 150 | M26: =H26*I26+J26*K26+L26
G27: Strong pre-launch | H27: 5000 | I27: 0.05 | J27: 2000 | K27: 0.4 | L27: 200 | M27: =H27*I27+J27*K27+L27
G28: Aggressive marketing | H28: 8000 | I28: 0.05 | J28: 3000 | K28: 0.4 | L28: 200 | M28: =H28*I28+J28*K28+L28
G29: Danny leverage play | H29: 10000 | I29: 0.05 | J29: 3000 | K29: 0.3 | L29: 250 | M29: =H29*I29+J29*K29+L29
G30: Home run | H30: 15000 | I30: 0.07 | J30: 5000 | K30: 0.3 | L30: 300 | M30: =H30*I30+J30*K30+L30
G31: Campaign multiplier (mid-campaign growth) | H31: 1.6 | I31: Typical range: 1.3x-2.0x
G32: TOTAL BACKERS OVER CAMPAIGN | H32: =M25*$H$31 | I32: =M26*$H$31 | J32: =M27*$H$31 | K32: =M28*$H$31 | L32: =M29*$H$31 | M32: =M30*$H$31
H33: Current | I33: Moderate | J33: Strong | K33: Aggressive | L33: Danny Lvg | M33: Home Run
G35: DANNY FOLLOWER FUNNEL
G36: Danny's IG followers | H36: 39000 | I36: Current count
G37: % who see a post (organic reach) | H37: 0.15 | I37: IG avg organic reach ~10-20%
G38: Impressions per post | H38: =H36*H37
G39: % who click landing page | H39: 0.05 | I39: Strong CTA needed
G40: Landing page visitors | H40: =H38*H39
G41: % who sign up (email) | H41: 0.25 | I41: Good LP converts 20-35%
G42: Email signups from 1 Danny post | H42: =H40*H41
G43: Posts over 6 months | H43: 50 | I43: ~2/week mentioning the game
G44: Diminishing returns factor | H44: 0.3 | I44: Most convert early
G45: TOTAL EMAILS FROM DANNY | H45: =ROUND(H42+(H43-1)*H42*H44,0)

Sheet Kickstarters to watch
A1: https://www.kickstarter.com/projects/thegoddesskey/inner-codes-arcana?ref=discovery_category&total_hits=19939&category_id=273
A3: https://www.kickstarter.com/projects/bigcomet/dinkduel?ref=discovery_category&total_hits=19939&category_id=34
A5: https://www.kickstarter.com/projects/geoffkern/rambo-ranch?ref=discovery_category&total_hits=19939&category_id=273
A7: https://www.kickstarter.com/projects/mintpanda/medieval-madness?ref=discovery_category&total_hits=59982&category_id=34

Sheet Goats Comparison
A1: # Sold | B1: Cost | C1: Total
A2: 771 | B2: 20 | C2: =B2*A2
A3: 1751 | B3: 38 | C3: =B3*A3
C4: =SUM(C2:C3)
A6: Average paid per backer | B6: =C4/(A3+A2)
